Workbook
Name NativeTimeline_Order_Date: #N/A
Name Sales_Data: REFERENCE!$C$60
Name Slicer_Brand: #N/A
Name Slicer_Category: #N/A
Name Slicer_Category1: #N/A
Name Slicer_City: #N/A
Name Slicer_Full_Time_Result: #N/A
Name Slicer_Home_Team: #N/A
Name Slicer_League: #N/A
Name Slicer_Notes: #N/A
Name Slicer_Payment_Method: #N/A
Name Slicer_Product: #N/A
Name Slicer_Region: #N/A
Name Slicer_Salesperson: #N/A
Name Slicer_Season: #N/A
Name Slicer_Stadium: #N/A

Sheet Sheet1
A1: Branch | B1: Region | C1: Revenue (Rs.) | D1: Cost (Rs.) | E1: Profit (Rs.) | F1: Manager | G1: Confidential Notes
A2: Branch C | B2: East | C2: 610000 | D2: 510000 | E2: 100000 | F2: Simran Kaur | G2: Under review
A3: Branch A | B3: North | C3: 850000 | D3: 620000 | E3: 230000 | F3: Karan Malhotra | G3: Lease renewal pending
A4: Branch B | B4: South | C4: 920000 | D4: 640000 | E4: 280000 | F4: Divya Krishnan | G4: Staff shortage Q3
A5: Branch D | B5: West | C5: 1050000 | D5: 700000 | E5: 350000 | F5: Farah Khan | G5: Top performer

Sheet Sheet2
A1: Category | B1: Week 1 | C1: Week 2 | D1: Week 3 | E1: Week 4 | F1: TOTAL | G1: AVERAGE
A2: Groceries | B2: 2200 | C2: 1950 | D2: 2400 | E2: 2100 | F2: =SUM(B2:E2) -> 8650 | G2: =AVERAGE(B2:E2) -> 2162.5
A3: Transport | B3: 800 | C3: 750 | D3: 900 | E3: 820 | F3: =SUM(B3:E3) -> 3270 | G3: =AVERAGE(B3:E3) -> 817.5
A4: Utilities | B4: 1500 | C4: 1500 | D4: 1600 | E4: 1550 | F4: =SUM(B4:E4) -> 6150 | G4: =AVERAGE(B4:E4) -> 1537.5
A5: Entertainment | B5: 600 | C5: 900 | D5: 400 | E5: 750 | F5: =SUM(B5:E5) -> 2650 | G5: =AVERAGE(B5:E5) -> 662.5
A6: Miscellaneous | B6: 350 | C6: 500 | D6: 300 | E6: 450 | F6: =SUM(B6:E6) -> 1600 | G6: =AVERAGE(B6:E6) -> 400
A7: TOTAL | B7: =SUM(B2:B6) -> 5450 | C7: =SUM(C2:C6) -> 5600 | D7: =SUM(D2:D6) -> 5600 | E7: =SUM(E2:E6) -> 5670 | F7: =SUM(B7:E7) -> 22320

Sheet Sheet3
A1: A: Roll No. | B1: B: Week Start Date | C1: C: Month | D1: D: Quarter Label | E1: E: Odd Numbers | F1: F: Invoice No.
A2: 1 | B2: 46272 | C2: January | D2: Q1 | E2: 1 | F2: INV-001
A3: 2 | B3: 46279 | C3: February | D3: Q2 | E3: 3 | F3: INV-002
A4: 3 | B4: 46286 | C4: March | D4: Q3 | E4: 5 | F4: INV-003
A5: 4 | B5: 46293 | C5: April | D5: Q4 | E5: 7 | F5: INV-004
A6: 5 | B6: 46300 | C6: May | D6: Q1 | E6: 9 | F6: INV-005
A7: 6 | B7: 46307 | C7: June | D7: Q2 | E7: 11 | F7: INV-006
A8: 7 | B8: 46314 | C8: July | D8: Q3 | E8: 13 | F8: INV-007

Sheet Sheet4
A1: Full Name | B1: First Name (Q1) | C1: Last Name (Q1) | D1: Email | E1: Username (Q2) | F1: Phone (raw) | G1: Phone Formatted (Q3) | H1: Initials
A2: Nikhil Rane | B2: Nikhil | C2: Rane | D2: nikhil.rane@gmail.com | E2: nikhil.rane | F2: 9876543210 | G2: +91-98765-43210' | H2: N.R
A3: Sarah Mathew | B3: Sarah | C3: Mathew | D3: sarah.mathew@outlook.com | E3: sarah.mathew | F3: 9123456780 | G3: +91-91234-56780' | H3: S.M
A4: Farhan Sheikh | B4: Farhan | C4: Sheikh | D4: farhan.sheikh@yahoo.co.in | E4: farhan.sheikh | F4: 9988776655 | G4: +91-99887-76655' | H4: F.S
A5: Divya Krishnan | B5: Divya | C5: Krishnan | D5: divya.krishnan@gmail.com | E5: divya.krishnan | F5: 9012345678 | G5: +91-90123-45678' | H5: D.K
A6: Om Prakash | B6: Om | C6: Prakash | D6: om.prakash@companymail.com | E6: om.prakash | F6: 9765432109 | G6: +91-97654-32109' | H6: O.P

Sheet Sheet5
A1: Roll No. | B1: Student Name | C1: Grade Level | D1: Marks | E1: Subject | F1: Attendance %
A2: 1 | B2: Kabir Singh | C2: A | D2: 81 | E2: Maths | F2: 88
A3: 10 | B3: Arjun Bose | C3: A | D3: 67 | E3: Science | F3: 90
A4: 12 | B4: Rohan Mehta | C4: A | D4: 34 | E4: Science | F4: 78
A5: 4 | B5: Diya Menon | C5: B | D5: 96 | E5: Maths | F5: 60
A6: 5 | B6: Ishita Kapoor | C6: B | D6: 73 | E6: Science | F6: 92
A7: 15 | B7: Meera Pillai | C7: B | D7: 40 | E7: Science | F7: 95
A8: 8 | B8: Aditya Verma | C8: C | D8: 96 | E8: Maths | F8: 65
A9: 7 | B9: Ananya Das | C9: C | D9: 88 | E9: Maths | F9: 55

Sheet Sheet6
A1: Tax Rate: | B1: 0.18
A3: Item | B3: Quantity | C3: Unit Cost | D3: Line Total | E3: Tax @ Rate | F3: Grand Total
A4: Chairs | B4: 20 | C4: 1200 | D4: 24000 | E4: =D4*B$1 -> 4320 | F4: 28320
A5: Tables | B5: 10 | C5: 3500 | D5: 35000 | E5: =D5*B$1 -> 6300 | F5: 41300
A6: Cabinets | B6: 5 | C6: 8000 | D6: 40000 | E6: =D6*B$1 -> 7200 | F6: =D6+E6 -> 47200
A7: Shelves | B7: 15 | C7: 950 | D7: 14250 | E7: =D7*B$1 -> 2565 | F7: 16815

Sheet Sheet7
A1: Total Revenue (Rs.): | B1: =SUM(D6:D25) -> 194430
A2: Total Profit (Rs.): | B2: =SUM(E6:E25) -> 45638
A3: Average Order Value (Rs.): | B3: 9147.6
A5: Order ID | B5: Customer | C5: Region | D5: Amount (Rs.) | E5: Profit (Rs.)
A6: ORD-200 | B6: Deepak Joshi | C6: West | D6: 9700 | E6: 1412
A7: ORD-201 | B7: Deepak Joshi | C7: South | D7: 20333 | E7: 9000
A8: ORD-202 | B8: Deepak Joshi | C8: West | D8: 5025 | E8: 900
A9: ORD-203 | B9: Deepak Joshi | C9: South | D9: 12319 | E9: 1848
A10: ORD-204 | B10: Farah Khan | C10: East | D10: 3800 | E10: 9876
A11: ORD-205 | B11: Ravi Kumar | C11: North | D11: 4323 | E11: 900
A12: ORD-206 | B12: Farah Khan | C12: West | D12: 11755 | E12: 2000
A13: ORD-207 | B13: Kavita Menon | C13: South | D13: 12713 | E13: 1907
A14: ORD-208 | B14: Ravi Kumar | C14: North | D14: 12209 | E14: 1831
A15: ORD-209 | B15: Ravi Kumar | C15: South | D15: 2975 | E15: 446
A16: ORD-210 | B16: Deepak Joshi | C16: North | D16: 5963 | E16: 894
A17: ORD-211 | B17: Farah Khan | C17: East | D17: 14748 | E17: 2212
... A25: ORD-219 | B25: Ravi Kumar | C25: North | D25: 2487 | E25: 999

Sheet IS functions
B1: ISBLANK(value)
B2: If a cell is blank, it returns TRUE.
B3: If a cell is not blank, it returns FALSE.
B5: Values | C5: Formulas
B6: Orange
B7: TRUE | C7: =ISBLANK(B7) -> FALSE
B8: FALSE | C8: =ISBLANK(B8) -> FALSE
C9: =ISBLANK(B9) -> TRUE
C10: =ISBLANK(B10) -> FALSE
B11: King Cobra | C11: =ISBLANK(B11) -> FALSE
B14: ISERR(value)
B15: Checks whether a value is an error (#VALUE!, #REF!, #DIV/0!, #NUM!, #NAME?, or #NULL!) excluding #N/A, and returns TRUE or FALSE
B17: Values | C17: Formula
B18: #VALUE! | C18: =ISERR(B18) -> TRUE
B19: #REF! | C19: =ISERR(B19) -> TRUE
B20: #DIV/0! | C20: =ISERR(B20) -> TRUE
B21: #NUM! | C21: =ISERR(B21) -> TRUE
B22: #NAME? | C22: =ISERR(B22) -> TRUE
B23: #NULL! | C23: =ISERR(B23) -> TRUE
B24: #N/A | C24: =ISERR(B24) -> FALSE
B25: Apple | C25: =ISERR(B25) -> FALSE
B28: ISERROR(value)
B29: Checks whether a value is an error (#N/A, #VALUE!, #REF!, #DIV/0!, #NUM!, #NAME?, or #NULL!), and returns TRUE or FALSE
B31: Values | C31: Formula
B32: #VALUE! | C32: =ISERROR(B32) -> TRUE
B33: #REF! | C33: =ISERROR(B33) -> TRUE
B34: #DIV/0! | C34: =ISERROR(B34) -> TRUE
B35: #NUM! | C35: =ISERROR(B35) -> TRUE
B36: #NAME? | C36: =ISERROR(B36) -> TRUE
B37: #NULL! | C37: =ISERROR(B37) -> TRUE
B38: #N/A | C38: =ISERROR(B38) -> TRUE
B39: Apple | C39: =ISERROR(B39) -> FALSE
B42: ISEVEN(value)
B43: Retursn TRUE if the number is even
B45: Values | C45: Formula
B46: 5 | C46: =ISEVEN(B46) -> FALSE
B47: 10 | C47: =ISEVEN(B47) -> TRUE
B48: 81/9 | C48: =ISEVEN(B48) -> #VALUE!
B49: Excel 2013 | C49: =ISEVEN(B49) -> #VALUE!
B52: ISODD(value)
...

Sheet Mathematical
B2: SUM(number1, [number2], [number3], [number4], …)
B3: Adds all the numbers in a range of cells
B5: Values | C5: Formula
B6: -5 | C6: =SUM(B6:B11) -> 40
B7: 15 | C7: =SUM(B6:B8,"5",TRUE,FALSE) -> 46
B8: 30
B9: 5
B10: TRUE
B11: FALSE
B14: AVERAGE(number1, [number2], [number3], [number4], …)
B15: Returns the average (arithmetic means) of its arguments, which can be numbers or names, arrays, or references that contain numbers
B17: Values | C17: Formula
B18: -5 | C18: =AVERAGE(B18:B23) -> 13.333333
B19: 15 | C19: =AVERAGE(B18:B20,"5",TRUE,FALSE) -> 7.6666667
B20: 30
B21: 5
B22: TRUE
B23: FALSE
B26: AVERAGEA(value1, [value2], [value3], [value4], …)
B27: Returns the average (arithmetic means) of its arguments, evaluating text and FALSE in arguments as 0; TRUE evaluates as 1. Arguments can be numbers, names, arrays, or references.
B29: Values | C29: Formula
B30: -5 | C30: =AVERAGEA(B30:B35) -> 6.8333333
B31: 15 | C31: =AVERAGEA(B30:B32,"5",TRUE,FALSE) -> 7.6666667
B32: 30
B33: 5
B34: TRUE
B35: FALSE
B37: COUNT(value1, [value2], [value3], …)
B38: Counts the number of cells in a range that contain numbers
B40: Values | C40: Formula
B41: -5 | C41: =COUNT(B41:B46) -> 3
B42: 15 | C42: =COUNT(B41:B43,"5",TRUE,FALSE) -> 6
B43: 30
B44: 5
B45: TRUE
B46: FALSE
B49: COUNTA(value1, [value2], [value3], …)
B50: Counts the number of cells in a range that are not empty
B53: Values | C53: Formula
B54: -5 | C54: =COUNTA(B54:B59) -> 6
...

Sheet FIND& SEARCH
B3: FIND(find_text, within_text, [start_num])
B4: Returns the starting position of one text string within another text string. FIND is case-sensitive
B6: Data | D6: =FIND("r",B7) -> 3
B7: Marissa Kawser Ron | D7: =FIND("r",B7,1) -> 3
D8: =FIND("r",B7,2) -> 3
D9: =FIND("r",B7,3) -> 3
D10: =FIND("r",B7,4) -> 14
D11: =FIND("R",B7) -> 16
B13: SEARCH(find_text, within_text, [start_num])
B14: Returns the number of the character at which a specific character or text string is first found, reading left to right (not case-sensitive)
B16: Data | D16: =SEARCH("r",B17) -> 3
B17: Marissa Kawser Ron | D17: =SEARCH("r",B17,1) -> 3
B18: "Jon" come here | D18: =SEARCH("r",B17,2) -> 3
B19: The "boss" is here | D19: =SEARCH("r",B17,3) -> 3
D20: =SEARCH("r",B17,4) -> 14
D21: =SEARCH("R",B17) -> 3
D22: =SEARCH(" ",B18) -> 6
D23: =SEARCH("""",B19) -> 5
B27: SUBSTITUTE(text, old_text, new_text, [instance_num])
B28: Replaces existing text with new text in a text string
B30: Data
B31: Quantity Sold Sold | C31: =SUBSTITUTE(B31,"Sold","bought") -> Quantity bought bought
B32: Year 2008 | C32: =SUBSTITUTE(B31,"Sold","bought",1) -> Quantity bought Sold
B33: Year 2009 | C33: =SUBSTITUTE(B31,"Sold","bought",2) -> Quantity Sold bought
C34: =SUBSTITUTE(B32,"08","13") -> Year 2013
B37: REPLACE(old_text, start_num, num_chars, new_text)
B38: Replaces part of a text string with different text string
B40: Data
B41: Marissa Khan | C41: =REPLACE(B41,9,1,"kawser") -> Marissa kawserhan
B42: 2015 | C42: =REPLACE(B41,9,2,"Kawser") -> Marissa Kawseran
B43: 9876543210 | C43: =REPLACE(B41,9,3,"Kawser") -> Marissa Kawsern
C44: =REPLACE(B41,9,4,"Kawser") -> Marissa Kawser
C45: =REPLACE(B41,1,1,"Kawser") -> Kawserarissa Khan
C46: =REPLACE(B41,2,2,"Kawser") -> MKawserissa Khan
C47: =REPLACE(B41,3,3,"Kawser") -> MaKawsersa Khan
C48: =REPLACE(B41,4,4,"Kawser") -> MarKawser Khan

Sheet Date & time
B2: DATE(year, month, day)
B3: Returns the number that represents the date in Microsoft Excel date-time code
B5: Year | C5: Month | D5: Day
B6: 2015 | C6: 10 | D6: 15 | F6: =DATE(B6,C6,D6) -> 42292
B7: 2010 | C7: 5 | D7: 25 | F7: =DATE(2010,C6,D6) -> 40466
B8: 1805 | C8: 8 | D8: 23 | F8: =DATE(B8,C8,D8) -> 659499
B12: DATEVALUE(date_text)
B13: Converts a date in the form of text to a number that represents the date in the Microsoft Excel date-time code
B15: =DATEVALUE("25/10/2015") -> 42302
B16: =DATEVALUE("22 May, 2015") -> 42146
B17: =DATEVALUE("22-May-2015") -> 42146
B20: TIME(hour, minute, second)
B21: Converts hours, minutes, and seconds given as numbers to an Excel serial number, formatted with a time format
B23: Hour | C23: Minute | D23: Second
B24: 12 | C24: 30 | D24: 30 | F24: =TIME(B24,C24,D24) -> 0.52118056
B25: 16 | C25: 45 | D25: 30 | F25: =TIME(B25,C25,D25) -> 0.69826389
B26: 16 | C26: 48 | D26: 15 | F26: =TIME(B26,C26,D26) -> 0.70017361
B29: TIMEVALUE(time_text)
B30: Converts a text time to an Excel serial number for a time, a number from 0 (12:00:00 AM) to 0.999988424 (11:59:59 PM). Format the number with a time format after entering the formula
B32: =TIMEVALUE("2:50 PM") -> 0.61805556
B33: =TIMEVALUE("22-AUGUST-2015 2:50 PM") -> 0.61805556
B36: NOW()
B37: Returns the current date and time formatted as a date and time
B39: =NOW() -> 46312.447
B40: =NOW()+7 -> 46319.447
B43: TODAY()
B44: Returns the current date formatted as a date
B46: =TODAY() -> 46312
B49: YEAR, MONTH, DAY, HOUR, MINUTE and SECOND Functions
B50: All of these functions take one argument: serial_number
B52: Function Name
B53: YEAR(…) | D53: =YEAR(NOW()) -> 2026
B54: MONTH(…) | D54: =MONTH(NOW()) -> 10
B55: DAY(…) | D55: =DAY(NOW()) -> 17
B56: HOUR(…) | D56: =HOUR(NOW()) -> 10
B57: MINUTE(…) | D57: =MINUTE(NOW()) -> 44
B58: SECOND(…) | D58: =SECOND(NOW()) -> 19
B62: WEEKDAY(serial_number, [return_type])
B63: Returns a number from 1 to 7 identifying the day of the week from a date
B65: =WEEKDAY(NOW()) -> 7
...

Sheet REFERENCE
B2: ADDRESS(row_num, column_num, [abs_num], [a1], [sheet_text])
B3: Creates a cell reference as text, given specified row and column numbers
C5: Formula | D5: Result
C6: =_xlfn.FORMULATEXT(D6) -> =ADDRESS(2,3) | D6: =ADDRESS(2,3) -> $C$2
C7: =_xlfn.FORMULATEXT(D7) -> =ADDRESS(2,3,2) | D7: =ADDRESS(2,3,2) -> C$2
C8: =_xlfn.FORMULATEXT(D8) -> =ADDRESS(2,3,2,FALSE) | D8: =ADDRESS(2,3,2,FALSE) -> R2C[3]
C9: =_xlfn.FORMULATEXT(D9) -> =ADDRESS(2,3,1,FALSE,"[Book1]Sheet1") | D9: =ADDRESS(2,3,1,FALSE,"[Book1]Sheet1") -> [Book1]Sheet1!R2C3
C10: =_xlfn.FORMULATEXT(D10) -> =ADDRESS(2,3,4,FALSE,"EXCEL SHEET") | D10: =ADDRESS(2,3,4,FALSE,"EXCEL SHEET") -> 'EXCEL SHEET'!R[2]C[3]
B13: CHOOSE(index_num, value1, [value2], [value3], …)
B14: Chooses a value or action to perform from a list of values, based on an index number
B16: Data | G16: Formula | H16: Result | I16: Remarks
B17: Marissa | D17: =CHOOSE(3,B17,B18,B19,B20,B21,B22,) -> Excel BI | G17: =_xlfn.FORMULATEXT(H17) -> =CHOOSE(3,B17,B18,B19,B20,B21,B22) | H17: =CHOOSE(3,B17,B18,B19,B20,B21,B22) -> Excel BI | I17: Value of the 3rd list argument (value of cell B23)
B18: Excel | D18: =CHOOSE(5,B17,B18,B19,B20,B21,B22,B22) -> Power Pivot | G18: =_xlfn.FORMULATEXT(H18) -> =CHOOSE(5,B17,B18,B19,B20,B21,B22) | H18: =CHOOSE(5,B17,B18,B19,B20,B21,B22) -> Power Pivot | I18: Value of the 5th list argument (value of cell B25)
B19: Excel BI
B20: Power Query
B21: Power Pivot
B22: Power Map
B25: Array Form: | C25: INDEX(array, row_num, [column_num])
B26: Return the value of a specified cell or array of cells
B27: Reference Form: | C27: INDEX(reference, row_num, [column_num], [area_num])
B28: Returns a reference to specified cells
B30: Array Form Example
B32: Data | C32: Data | G32: Formula | H32: Result | I32: Remarks
B33: Apples | C33: Lemons | D33: =INDEX(B33:C34,2,2) -> Pears | G33: =_xlfn.FORMULATEXT(H33) -> =INDEX(B33:C34,2,2) | H33: =INDEX(B33:C34,2,2) -> Pears | I33: INDEX function in Array format.
B34: Bananas | C34: Pears | D34: {=INDEX(B33:C34,0,1)} -> Apples | G34: =_xlfn.FORMULATEXT(H34) -> {=INDEX(B33:C34,0,1)} | H34: {=INDEX(B33:C34,0,1)} -> Apples | I34: INDEX function in Array format and entered as Array formula. Returns the entire 1st column of the range.
D35: Bananas | G35: =_xlfn.FORMULATEXT(H35) -> {=INDEX(B33:C34,0,1)} | H35: Bananas | I35: INDEX function in Array format and entered as Array formula. Returns the entire 1st column of the range.
B39: Fruit 1 | C39: Price | D39: Count | G39: Formula | H39: Result | I39: Remarks
B40: Apples | C40: 0.69 | D40: 40 | G40: =_xlfn.FORMULATEXT(H40) -> =INDEX(B40:D44,3,3) | H40: =INDEX(B40:D44,3,3) -> 15 | I40: The intersection of the 3rd row and 3rd column in the range B64: D68. Returns the cell reference D66. D66 has value 15, so the formula returns 15
B41: Bananas | C41: 0.34 | D41: 38 | G41: =_xlfn.FORMULATEXT(H41) -> =INDEX((B40:D44,B47:D50),3,2,2) | H41: =INDEX((B40:D44,B47:D50),3,2,2) -> 1.25 | I41: The intersection of the 3rd row and 2nd column in the range B71: D74 as area_num is 2. Returns the cell reference C73. C73 has value 1.25. So the formula returns 1.25 value.
B42: Lemons | C42: 0.55 | D42: 15 | G42: =_xlfn.FORMULATEXT(H42) -> =SUM(D40:INDEX(B40:D44,5,3)) | H42: =SUM(D40:INDEX(B40:D44,5,3)) -> 158 | I42: INDEX part of this formula returns cell reference D68. SUM function returns the sum of range D64: D68.
B43: Oranges | C43: 0.25 | D43: 25
B44: Pears | C44: 0.59 | D44: 40
G45: =INDEX(B40:D44,3,3) -> 15
B46: Fruit 2 | C46: Price | D46: Count | G46: =INDEX((B40:D44,B47:D50),3,2,2) -> 1.25
B47: Almonds | C47: 2.8 | D47: 10 | G47: =SUM(D40:INDEX(B40:D44,5,3)) -> 158
B48: Cashews | C48: 3.55 | D48: 16
B49: Peanuts | C49: 1.25 | D49: 20
B50: Walnuts | C50: 1.75 | D50: 12
B53: INDIRECT(ref_text, [a1])
B54: Returns the reference specified by a text string
...

Sheet LOGICAL
B2: AND(logical1, [logical2], [logical3], [logical4], …)
B3: Checks whether all arguments are TRUE, and returns TRUE when all arguments are TRUE
G5: Formula | H5: Result | I5: Remarks
C6: =AND(TRUE,TRUE,TRUE) -> TRUE | G6: =_xlfn.FORMULATEXT(H6) -> =AND(TRUE,TRUE,TRUE) | H6: =AND(TRUE,TRUE,TRUE) -> TRUE | I6: All arguments are TRUE, the formula returns TRUE.
C7: =AND(TRUE,FALSE,TRUE,TRUE,TRUE,TRUE) -> FALSE | G7: =_xlfn.FORMULATEXT(H7) -> =AND(TRUE,FALSE,TRUE,TRUE,TRUE,TRUE) | H7: =AND(TRUE,FALSE,TRUE,TRUE,TRUE,TRUE) -> FALSE | I7: One argument is FALSE, the formula returns FALSE.
C8: =AND(1+2=3,3+4=7) -> TRUE | G8: =_xlfn.FORMULATEXT(H8) -> =AND(1+2=3,3+4=7) | H8: =AND(1+2=3,3+4=7) -> TRUE | I8: All arguments are TRUE, the formula returns TRUE.
B12: OR(logical1, [logical2], [logical3], [logical4], …)
B13: Checks whether any of the arguments is TRUE, and returns TRUE or FALSE. Returns FALSE only when all arguments are FALSE
G15: Formula | H15: Result | I15: Remarks
G16: =_xlfn.FORMULATEXT(H16) -> =OR(TRUE) | H16: =OR(TRUE) -> TRUE | I16: One argument is TRUE
G17: =_xlfn.FORMULATEXT(H17) -> =OR(1+1=1,2+2=5) | H17: =OR(1+1=1,2+2=5) -> FALSE | I17: All arguments evaluate to FALSE
G18: =_xlfn.FORMULATEXT(H18) -> =OR(TRUE,FALSE,TRUE) | H18: =OR(TRUE,FALSE,TRUE) -> TRUE | I18: At least one argument is TRUE
G19: =_xlfn.FORMULATEXT(H19) -> =IF(OR(1+1=1,2+2=5,5+5=10),"Answer if true","Answer if false") | H19: =IF(OR(1+1=1,2+2=5,5+5=10),"Answer if true","Answer if false") -> Answer if true | I19: One of the OR arguments are true.
E21: =OR(TRUE) -> TRUE
E22: =OR(1+1=1,2+2=5) -> FALSE
E23: =OR(TRUE,FALSE,FALSE) -> TRUE
E24: =IF(OR(1+1=1,2+2=5,5+5=10),"Answer if true","Answer if false") -> Answer if true
B27: NOT(logical)
B28: Changes FALSE to TRUE, or TRUE to FALSE
G30: Formula | H30: Result | I30: Remarks
G31: =_xlfn.FORMULATEXT(H31) -> =NOT(FALSE) | H31: =NOT(FALSE) -> TRUE | I31: Reverses FALSE
G32: =_xlfn.FORMULATEXT(H32) -> =NOT(TRUE) | H32: =NOT(TRUE) -> FALSE | I32: Reverses TRUE
G33: =_xlfn.FORMULATEXT(H33) -> =NOT(1+1=5) | H33: =NOT(1+1=5) -> TRUE | I33: Reverses FALSE
B35: XOR(logical1, [logical2], [logical3], …)
B36: Returns a logical 'Exclusive Or' of all arguments
G38: Formula | H38: Result | I38: Remarks
G39: =_xlfn.FORMULATEXT(H39) -> =XOR(3>0,2<9) | H39: =_xlfn.XOR(3>0,2<9) -> FALSE | I39: Because one of the two tests evaluates to True, TRUE is returned.
G40: =_xlfn.FORMULATEXT(H40) -> #N/A | I40: Because all test results evaluate to False, FALSE is returned. At least one of the test results must evaluate to True to return TRUE.
G42: =_xlfn.XOR(3>0,2<9) -> FALSE
G43: =_xlfn.XOR(3>12,4>6) -> FALSE

Sheet MISC.
B2: AREAS(reference)
B3: Returns the number of areas in a reference. An area is range of contiguous cells or a single cell
G5: Formula | H5: Result | I5: Remarks
C6: =AREAS(B2:D4) -> 1 | G6: =AREAS(B2:D4) | H6: 1 | I6: Number of areas in the range
C7: =AREAS((B2:D4,E5,F6:I9)) -> 3 | G7: =AREAS((B2:D4,E5,F6:I9)) | H7: 3 | I7: Number of areas in the range
B8: =AREAS(B2:D4 B2) -> 1 | G8: =AREAS(B2:D4 B2) | H8: 1 | I8: Number of areas in the range
B11: CHAR(number)
B12: Returns the character specified by the code number from the character set for your computer
G14: Formula | H14: Result | I14: Remarks
D15: =CHAR(65) -> A | G15: =CHAR(65) | H15: A | I15: Displays the character represented by 65 in the computer's character set.
D16: =CHAR(33) -> ! | G16: =CHAR(33) | H16: ! | I16: Displays the character represented by 33 in the computer's character set.
D17: =CHAR(7) -> _x0007_
B20: CODE(text)
B21: Returns a numeric code for the first character in a text string, in the character set used by your computer
G23: Formula | H23: Result | I23: Remarks
D24: =CODE("A") -> 65 | G24: =CODE("A") | H24: 65 | I24: Returns the numeric code of character A.
D25: =CODE("MARISSA") -> 77 | G25: =CODE("Marissa") | H25: 77 | I25: Returns the numeric code of the first character M of Marissa text.
D26: =CODE("!") -> 33 | G26: =CODE("!") | H26: 33 | I26: Returns the numeric code of character !
D27: =CODE("?") -> 63 | G27: =CODE("?") | H27: 63 | I27: Returns the numeric code of character ?
B30: CLEAN(text)
B31: Removes all non-printable characters from text
B32: Examples of Non-Printable Characters are: Tab, New Line characters. Their codes are 9 and 10
B34: Data | G34: Formula | H34: Result | I34: Remarks
B35: Sales Data | D35: =CLEAN(B35) -> Sales Data | G35: =CLEAN(B32) | H35: Sales Data | I35: This formula cleans up the TAB and NEW LINE non-printable characters from the text.
B39: TRIM(text)
B40: Removes all spaces from a text string except for single spaces between words
B42: Data | G42: Formula | H42: Result | I42: Remarks
B43: Excel Dashboard | D43: =TRIM(B43) -> Excel Dashboard | G43: =TRIM(B40) | H43: Excel Dashboard | I43: Removes all the spaces except for single spaces between words
B44: Titas Gas | D44: =TRIM(B44) -> Titas Gas | G44: =TRIM(" Titas Gas ") | H44: Titas Gas | I44: Removes all the spaces except for single spaces between words
B48: LEN(text)
B49: Returns the number of characters in a text string
B51: Data | G51: Formula | H51: Result | I51: Remarks
B52: Microsoft Excel | D52: =LEN(B52) -> 15 | G52: =LEN(B50) | H52: 15 | I52: Total 15 characters in the cell B30
D53: =LEN(B53) -> 0 | G53: =LEN(B51) | H53: 0 | I53: No characters in the cell B31
D54: =LEN(B54) -> 4 | G54: =LEN(B52) | H54: 4 | I54: 4 Space characters in the cell B32
B55: One | D55: =LEN(B55) -> 3 | G55: =LEN(B54) | H55: 10 | I55: Before Marissa there are 3 space characters.
B56: Marissa | D56: =LEN(B56) -> 10
B60: COLUMN([reference])
B61: Returns the column number of a reference
B62: ROW([reference])
...

Sheet RANK
B2: RANK(number, ref, [order])
B3: This function is available for compatibility with Excel 2007 and other.
B4: Returns the rank of a number in a list of numbers: its size relative to other values in the list
B6: Data | G6: Formula | H6: Result | I6: Remarks
B7: 7 | D7: =RANK(B8,B7:B11) -> 2 | G7: =RANK(B8,B7:B11) | H7: 2 | I7: Order is 0 or omitted, the values are arranged in descending order.
B8: 3.5 | D8: =RANK(B9,B7:B11) -> 2 | G8: =RANK(B9,B7:B11) | H8: 2 | I8: RANK function gives duplicate numbers same rank.
B9: 3.5 | D9: =RANK(B10,B7:B11,1) -> 1 | G9: =RANK(B10,B7:B11,1) | H9: 1 | I9: Order is 1, the values are arranged in ascending order.
B10: 1 | D10: =RANK(B10,B7:B11,0) -> 5 | G10: =RANK(B10,B7:B11,0) | H10: 5 | I10: Order is 0 or omitted, the values are arranged in descending order.
B11: 2
B14: RANK.AVG(number, ref, [order])
B15: Returns the rank of a number in a list of numbers: its size relative to other values in the list; if more than one value has the same rank, the average rank is returned
B17: Data | G17: Formula | H17: Result | I17: Remarks
B18: 89 | D18: =_xlfn.RANK.AVG(B19,B18:B25) -> 4 | G18: =RANK.AVG(B28,B27:B34) | H18: 4 | I18: Numbers are arranged in descending order and 90 ranks 4.
B19: 90 | D19: =_xlfn.RANK.AVG(B24,B18:B25,1) -> 1.5 | G19: =RANK.AVG(B33,B27:B34,1) | H19: 1.5 | I19: You get the average rank of number 85 when the numbers are in ascending order.
B20: 87 | D20: =_xlfn.RANK.AVG(B25,B18:B25,1) -> 7.5 | G20: =RANK.AVG(B34,B27:B34,1) | H20: 7.5 | I20: You get the average rank of number 98 when the numbers are in ascending order.
B21: 98
B22: 96
B23: 85
B24: 85
B25: 98
B28: RANK.EQ(number, ref, [order])
B29: Returns the rank of a number in a list of numbers: its size relative to other values in the list; if more than one value has the same rnak, the top rank of that set of values is returned
B31: Data | G31: Formula | H31: Result | I31: Remarks
B32: 89 | D32: =_xlfn.RANK.EQ(B33,B32:B39) -> 4 | G32: =RANK.EQ(B43,B42:B49) | H32: 4 | I32: Numbers are arranged in descending order and 90 ranks 4.
B33: 90 | D33: =_xlfn.RANK.EQ(B38,B32:B39,1) -> 1 | G33: =RANK.EQ(B48,B42:B49,1) | H33: 1 | I33: You get the top rank of number 85 when the numbers are in ascending order.
B34: 87 | D34: =_xlfn.RANK.EQ(B39,B32:B39,1) -> 7 | G34: =RANK.EQ(B49,B42:B49,1) | H34: 7 | I34: You get the top rank of number 98 when the numbers are in ascending order.
B35: 98 | H35: 7 | I35: You get the top rank of number 98 when the numbers are in ascending order.
B36: 96
B37: 85
B38: 85
B39: 98

Sheet CONDITIONAL
B2: =AVERAGEIF(range, criteria, [average_range])
B3: Finds average (arithmetic mean) for the cells specified by a given condition or criteria
B5: Region | C5: Sales | F5: Formula | G5: Result | H5: Remarks
B6: East | C6: 500 | F6: =AVERAGEIF(B6:B27,"East",C6:C27) | G6: 267.5 | H6: Average of all the Sales for East region.
B7: West | C7: 50 | F7: =AVERAGEIF(B6:B27,"North",C6:C27) | G7: 62.5 | H7: Average of all the Sales for North region.
B8: North | C8: 100 | F8: =AVERAGEIF(B6:B27,"North*",C6:C27) | G8: 55 | H8: Average of all the Sales for North region (including North (New Office) region).
B9: South | C9: 25 | F9: =AVERAGEIF(B6:B27,"*New Office",C6:C27) | G9: 35 | H9: Average of all the Sales for the New Offices.
B10: Mid West | C10: 200 | F10: =AVERAGEIF(B6:B27,">=4",C6:C27) | G10: 58.75 | H10: Average of all the Sales for the values greater than or equal to 4.
B11: South New Office | C11: 30 | F11: =AVERAGEIF(B6:B27,5,C6:C27) | G11: 75 | H11: Average of all the Sales for the values equal to 5.
B12: East | C12: 35 | F12: =AVERAGEIF(B6:B27,TRUE,C6:C27) | G12: 110 | H12: Average of all the Sales for the values equal to TRUE statement.
B13: West | C13: 50 | F13: =AVERAGEIF(B6:B27,FALSE,C6:C27) | G13: 77.5 | H13: Average of all the Sales for the values equal to FALSE statement.
B14: South | C14: 15
B15: North | C15: 25 | F15: =AVERAGEIF(B6:B27,"East",C6:C27) -> 267.5
B16: North New Office | C16: 40 | F16: =AVERAGEIF(B6:B27,"North",C6:C27) -> 62.5
B17: 5 | C17: 50 | F17: =AVERAGEIF(B6:B27,"North*",C6:C27) -> 55
B18: 5 | C18: 100 | F18: =AVERAGEIF(B6:B27,"*New Office",C6:C27) -> 35
B19: 2 | C19: 200 | F19: =AVERAGEIF(B6:B27,">=4",C6:C27) -> 58.75
B20: 4 | C20: 35 | F20: =AVERAGEIF(B6:B27,5,C6:C27) -> 75
B21: 2 | C21: 45 | F21: =AVERAGEIF(B6:B27,TRUE,C6:C27) -> 110
B22: 4 | C22: 50 | F22: =AVERAGEIF(B6:B27,FALSE,C6:C27) -> 77.5
B23: TRUE | C23: 90
B24: FALSE | C24: 100
B25: TRUE | C25: 125
B26: TRUE | C26: 115
B27: FALSE | C27: 55
D30: SUMIF(range, criteria, [sum_range])
B31: Adds the cells specified by a given condition or criteria
B33: Region | C33: Sales | F33: Formula | G33: Result | H33: Remarks
B34: East | C34: 500 | F34: =SUMIF(B36:B57,"East",C36:C57) | G34: 535 | H34: Sum of all the Sales for East region.
B35: West | C35: 50 | F35: =SUMIF(B36:B57,"North",C36:C57) | G35: 125 | H35: Sum of all the Sales for North region.
B36: North | C36: 100 | F36: =SUMIF(B36:B57,"North*",C36:C57) | G36: 165 | H36: Sum of all the Sales for North region (including North (New Office) region).
B37: South | C37: 25 | F37: =SUMIF(B36:B57,"*New Office",C36:C57) | G37: 70 | H37: Sum of all the Sales for the New Offices.
B38: Mid West | C38: 200 | F38: =SUMIF(B36:B57,">=4",C36:C57) | G38: 235 | H38: Sum of all the Sales for the values greater than or equal to 4.
B39: South New Office | C39: 30 | F39: =SUMIF(B36:B57,5,C36:C57) | G39: 150 | H39: Sum of all the Sales for the values equal to 5.
B40: East | C40: 35 | F40: =SUMIF(B36:B57,TRUE,C36:C57) | G40: 330 | H40: Sum of all the Sales for the values equal to TRUE statement.
B41: West | C41: 50 | F41: =SUMIF(B36:B57,FALSE,C36:C57) | G41: 155 | H41: Sum of all the Sales for the values equal to FALSE statement.
B42: South | C42: 15
B43: North | C43: 25 | F43: =SUMIF(B36:B57,"East",C36:C57) -> 35
B44: North New Office | C44: 40 | F44: =SUMIF(B36:B57,"North",C36:C57) -> 125
B45: 5 | C45: 50 | F45: =SUMIF(B36:B57,"North*",C36:C57) -> 165
...

Sheet LOOKUP
B2: MATCH(lookup_value, lookup_array, [match_type])
B3: Returns the relative position of an item in an array that matches a specified value in a specified order
B5: Product | C5: Count1 (Ascending) | D5: Count2 (Descending) | E5: Count3 (No Order)
B6: Apple | C6: 35 | D6: 45 | E6: 25 | G6: =MATCH(41,C6:C9,1) -> 3
B7: Orange | C7: 38 | D7: 40 | E7: 30 | G7: =MATCH(41,C6:C9,0) -> #N/A
B8: Banana | C8: 40 | D8: 38 | E8: 28 | G8: =MATCH(41,C6:C9,-1) -> #N/A
B9: Pears | C9: 45 | D9: 35 | E9: 15 | G9: =MATCH(41,D6:D9,-1) -> 1
G10: =MATCH(28,E6:E9,0) -> 3
B13: LOOKUP(lookup_value, lookup_vector, [result_vector])
B14: Looks up a value either from a one-row or one-column range or from an array. Provided for backward compatibility
B16: Part Number | C16: Serial | D16: Part Price | E16: Status
B17: A001 | C17: 10 | D17: 200 | E17: In Stock | F17: =LOOKUP("A003",B17:B22,D17:D22) -> 300
B18: A002 | C18: 20 | D18: 500 | E18: In Stock | F18: =LOOKUP(20,C17:C22,D17:D22) -> 500
B19: A003 | C19: 30 | D19: 300 | E19: In Stock | F19: =LOOKUP(25,C17:C22,D17:D22) -> 500
B20: A004 | C20: 40 | D20: 150 | E20: In Stock | F20: =LOOKUP(5,C17:C22,D17:D22) -> #N/A
B21: A005 | C21: 50 | D21: 225
B22: A006 | C22: 60 | D22: 525
B25: HLOOKUP(lookup_value, table_array, row_index_num, [range_lookup])
B26: Looks for a value in the top row of a table or array of values and return the value in the same column from a row you specify
B28: Month | C28: Axles | D28: Bearings | E28: Bolts
B29: Jan | C29: 4 | D29: 7 | E29: 9 | F29: =HLOOKUP("Axles",B28:E31,2,TRUE) -> 4
B30: Feb | C30: 5 | D30: 8 | E30: 10 | F30: =HLOOKUP("Bearings",C28:E31,3,FALSE) -> 8
B31: Mar | C31: 6 | D31: 9 | E31: 11 | F31: =HLOOKUP("B",B28:E31,3,TRUE) -> 5
B34: VLOOKUP(lookup_value, table_array, col_index_num, [range_lookup])
B35: Looks for a value in the leftmost column in a table, then returns a value in the same row from a column you specify. By default, the table must be sorted in an ascending order
B37: ID | C37: first name | D37: last name | E37: title | F37: Birth date | H37: Formula | I37: Result | J37: Remarks
B38: ID | C38: Davis | D38: Sara | E38: Sales Rep. | F38: 25062 | H38: =_xlfn.FORMULATEXT(I38) -> =VLOOKUP("Leal",C38:F43,3,FALSE) | I38: =VLOOKUP("Leal",C38:F43,3,FALSE) -> Sales Rep. | J38: In the range C59: F64, the formula looks up "Leal" in the first column, when found it shows the Title of Leal at 3rd column in the same row. FALSE returns an exact match.
B39: 105 | C39: Fontana | D39: Olivier | E39: V.P. of Sales | F39: 19043 | H39: =_xlfn.FORMULATEXT(I39) -> =VLOOKUP(111,B38:F43,5,FALSE) | I39: =VLOOKUP(111,B38:F43,5,FALSE) -> 21447 | J39: In the range B59: F64, the formula looks up value 111 in the frist column, when found it shows the Birth Date at 5th column in the same row. FALSE returns an exact match.
B40: 108 | C40: Leal | D40: Karina | E40: Sales Rep. | F40: 23253 | H40: =_xlfn.FORMULATEXT(I40) -> =VLOOKUP(110,B38:F43,4,FALSE) | I40: =VLOOKUP(110,B38:F43,4,FALSE) -> #N/A | J40: There is no ID as 110 in the first column of range B59: F64 and the VLOOKUP function will return an exact match. So the function returns #N/A.
B41: 111 | C41: Patten | D41: Michael | E41: Manager | F41: 21447 | H41: =_xlfn.FORMULATEXT(I41) -> =VLOOKUP(114,B38:F43,4,TRUE) | I41: =VLOOKUP(114,B38:F43,4,TRUE) -> Manager | J41: There is no ID as 114 in the first column of range B59: F64, but the VLOOKUP function will return an appropriate match, VLOOKUP function returns the Title of ID 111. 111 is the nearest value of 114 and less than 114.
B42: 115 | C42: Burke | D42: Brian | E42: Sales Mgr. | F42: 20182
B43: 120 | C43: Sousa | D43: Luis | E43: Sales Rep. | F43: 23049
B45: =VLOOKUP("Leal",C38:F43,3,FALSE) -> Sales Rep.
B46: =VLOOKUP(111,B38:F43,5,FALSE) -> 21447
B47: =VLOOKUP(110,B38:F43,4,FALSE) -> #N/A
B48: =VLOOKUP(114,B38:F43,4,TRUE) -> Manager

Sheet IF QS
A1: TOPIC 1: IF FUNCTION
A3: Dataset: Student Exam Results — Greenwood High School, Class X, Mathematics
A4: S.No | B4: Student Name | C4: Subject | D4: Marks (out of 100) | E4: Result (Q1) | F4: Grade (Q2) | G4: MERIT/NO MERIT | H4: RE EXAM/CLEARED | I4: PERFOMANCE | J4: % | K4: TOPPER
A5: 1 | B5: Aarav Sharma | C5: Mathematics | D5: 92 | E5: =IF(D5>=40,"PASS","FAIL") -> PASS | F5: =IF(D5>=90,"A+",IF(D5>=75,"A",IF(D5>=60,"B",IF(D5>=40,"C",IF(D5<40,"F"))))) -> A+ | G5: =IF(D5>=85,"MERIT","NO MERIT") -> MERIT | H5: =IF(D5<40,"RE - EXAM","CLEARED") -> CLEARED | I5: =IF(D5>=90,"EXCELLENT",IF(D5>=70,"GOOD",IF(D5>=40,"AVERAGE",IF(D5<40,"NEED IMPROVEMENT")))) -> EXCELLENT | J5: =D5/100 -> 0.92 | K5: =IF(D5=MAX($D$5:$D$16),"TOPPER","-") -> -
A6: 2 | B6: Priya Nair | C6: Mathematics | D6: 38 | E6: =IF(D6>=40,"PASS","FAIL") -> FAIL | F6: =IF(D6>=90,"A+",IF(D6>=75,"A",IF(D6>=60,"B",IF(D6>=40,"C",IF(D6<40,"F"))))) -> F | G6: =IF(D6>=85,"MERIT","NO MERIT") -> NO MERIT | H6: =IF(D6<40,"RE - EXAM","CLEARED") -> RE - EXAM | I6: =IF(D6>=90,"EXCELLENT",IF(D6>=70,"GOOD",IF(D6>=40,"AVERAGE",IF(D6<40,"NEED IMPROVEMENT")))) -> NEED IMPROVEMENT | J6: =D6/100 -> 0.38 | K6: =IF(D6=MAX($D$5:$D$16),"TOPPER","-") -> -
A7: 3 | B7: Rohan Mehta | C7: Mathematics | D7: 67 | E7: =IF(D7>=40,"PASS","FAIL") -> PASS | F7: =IF(D7>=90,"A+",IF(D7>=75,"A",IF(D7>=60,"B",IF(D7>=40,"C",IF(D7<40,"F"))))) -> B | G7: =IF(D7>=85,"MERIT","NO MERIT") -> NO MERIT | H7: =IF(D7<40,"RE - EXAM","CLEARED") -> CLEARED | I7: =IF(D7>=90,"EXCELLENT",IF(D7>=70,"GOOD",IF(D7>=40,"AVERAGE",IF(D7<40,"NEED IMPROVEMENT")))) -> AVERAGE | J7: =D7/100 -> 0.67 | K7: =IF(D7=MAX($D$5:$D$16),"TOPPER","-") -> -
A8: 4 | B8: Sneha Iyer | C8: Mathematics | D8: 45 | E8: =IF(D8>=40,"PASS","FAIL") -> PASS | F8: =IF(D8>=90,"A+",IF(D8>=75,"A",IF(D8>=60,"B",IF(D8>=40,"C",IF(D8<40,"F"))))) -> C | G8: =IF(D8>=85,"MERIT","NO MERIT") -> NO MERIT | H8: =IF(D8<40,"RE - EXAM","CLEARED") -> CLEARED | I8: =IF(D8>=90,"EXCELLENT",IF(D8>=70,"GOOD",IF(D8>=40,"AVERAGE",IF(D8<40,"NEED IMPROVEMENT")))) -> AVERAGE | J8: =D8/100 -> 0.45 | K8: =IF(D8=MAX($D$5:$D$16),"TOPPER","-") -> -
A9: 5 | B9: Kabir Singh | C9: Mathematics | D9: 81 | E9: =IF(D9>=40,"PASS","FAIL") -> PASS | F9: =IF(D9>=90,"A+",IF(D9>=75,"A",IF(D9>=60,"B",IF(D9>=40,"C",IF(D9<40,"F"))))) -> A | G9: =IF(D9>=85,"MERIT","NO MERIT") -> NO MERIT | H9: =IF(D9<40,"RE - EXAM","CLEARED") -> CLEARED | I9: =IF(D9>=90,"EXCELLENT",IF(D9>=70,"GOOD",IF(D9>=40,"AVERAGE",IF(D9<40,"NEED IMPROVEMENT")))) -> GOOD | J9: =D9/100 -> 0.81 | K9: =IF(D9=MAX($D$5:$D$16),"TOPPER","-") -> -
A10: 6 | B10: Ananya Das | C10: Mathematics | D10: 29 | E10: =IF(D10>=40,"PASS","FAIL") -> FAIL | F10: =IF(D10>=90,"A+",IF(D10>=75,"A",IF(D10>=60,"B",IF(D10>=40,"C",IF(D10<40,"F"))))) -> F | G10: =IF(D10>=85,"MERIT","NO MERIT") -> NO MERIT | H10: =IF(D10<40,"RE - EXAM","CLEARED") -> RE - EXAM | I10: =IF(D10>=90,"EXCELLENT",IF(D10>=70,"GOOD",IF(D10>=40,"AVERAGE",IF(D10<40,"NEED IMPROVEMENT")))) -> NEED IMPROVEMENT | J10: =IFERROR(D10/0,"CHECK DATA") -> CHECK DATA | K10: =IF(D10=MAX($D$5:$D$16),"TOPPER","-") -> -
A11: 7 | B11: Vivaan Rao | C11: Mathematics | D11: 58 | E11: =IF(D11>=40,"PASS","FAIL") -> PASS | F11: =IF(D11>=90,"A+",IF(D11>=75,"A",IF(D11>=60,"B",IF(D11>=40,"C",IF(D11<40,"F"))))) -> C | G11: =IF(D11>=85,"MERIT","NO MERIT") -> NO MERIT | H11: =IF(D11<40,"RE - EXAM","CLEARED") -> CLEARED | I11: =IF(D11>=90,"EXCELLENT",IF(D11>=70,"GOOD",IF(D11>=40,"AVERAGE",IF(D11<40,"NEED IMPROVEMENT")))) -> AVERAGE | J11: =D11/100 -> 0.58 | K11: =IF(D11=MAX($D$5:$D$16),"TOPPER","-") -> -
A12: 8 | B12: Ishita Kapoor | C12: Mathematics | D12: 96 | E12: =IF(D12>=40,"PASS","FAIL") -> PASS | F12: =IF(D12>=90,"A+",IF(D12>=75,"A",IF(D12>=60,"B",IF(D12>=40,"C",IF(D12<40,"F"))))) -> A+ | G12: =IF(D12>=85,"MERIT","NO MERIT") -> MERIT | H12: =IF(D12<40,"RE - EXAM","CLEARED") -> CLEARED | I12: =IF(D12>=90,"EXCELLENT",IF(D12>=70,"GOOD",IF(D12>=40,"AVERAGE",IF(D12<40,"NEED IMPROVEMENT")))) -> EXCELLENT | J12: =D12/100 -> 0.96 | K12: =IF(D12=MAX($D$5:$D$16),"TOPPER","-") -> TOPPER
A13: 9 | B13: Aditya Verma | C13: Mathematics | D13: 40 | E13: =IF(D13>=40,"PASS","FAIL") -> PASS | F13: =IF(D13>=90,"A+",IF(D13>=75,"A",IF(D13>=60,"B",IF(D13>=40,"C",IF(D13<40,"F"))))) -> C | G13: =IF(D13>=85,"MERIT","NO MERIT") -> NO MERIT | H13: =IF(D13<40,"RE - EXAM","CLEARED") -> CLEARED | I13: =IF(D13>=90,"EXCELLENT",IF(D13>=70,"GOOD",IF(D13>=40,"AVERAGE",IF(D13<40,"NEED IMPROVEMENT")))) -> AVERAGE | J13: =D13/100 -> 0.4 | K13: =IF(D13=MAX($D$5:$D$16),"TOPPER","-") -> -
A14: 10 | B14: Meera Pillai | C14: Mathematics | D14: 73 | E14: =IF(D14>=40,"PASS","FAIL") -> PASS | F14: =IF(D14>=90,"A+",IF(D14>=75,"A",IF(D14>=60,"B",IF(D14>=40,"C",IF(D14<40,"F"))))) -> B | G14: =IF(D14>=85,"MERIT","NO MERIT") -> NO MERIT | H14: =IF(D14<40,"RE - EXAM","CLEARED") -> CLEARED | I14: =IF(D14>=90,"EXCELLENT",IF(D14>=70,"GOOD",IF(D14>=40,"AVERAGE",IF(D14<40,"NEED IMPROVEMENT")))) -> GOOD | J14: =D14/100 -> 0.73 | K14: =IF(D14=MAX($D$5:$D$16),"TOPPER","-") -> -
A15: 11 | B15: Arjun Bose | C15: Mathematics | D15: 88 | E15: =IF(D15>=40,"PASS","FAIL") -> PASS | F15: =IF(D15>=90,"A+",IF(D15>=75,"A",IF(D15>=60,"B",IF(D15>=40,"C",IF(D15<40,"F"))))) -> A | G15: =IF(D15>=85,"MERIT","NO MERIT") -> MERIT | H15: =IF(D15<40,"RE - EXAM","CLEARED") -> CLEARED | I15: =IF(D15>=90,"EXCELLENT",IF(D15>=70,"GOOD",IF(D15>=40,"AVERAGE",IF(D15<40,"NEED IMPROVEMENT")))) -> GOOD | J15: =D15/100 -> 0.88 | K15: =IF(D15=MAX($D$5:$D$16),"TOPPER","-") -> -
A16: 12 | B16: Diya Menon | C16: Mathematics | D16: 34 | E16: =IF(D16>=40,"PASS","FAIL") -> FAIL | F16: =IF(D16>=90,"A+",IF(D16>=75,"A",IF(D16>=60,"B",IF(D16>=40,"C",IF(D16<40,"F"))))) -> F | G16: =IF(D16>=85,"MERIT","NO MERIT") -> NO MERIT | H16: =IF(D16<40,"RE - EXAM","CLEARED") -> RE - EXAM | I16: =IF(D16>=90,"EXCELLENT",IF(D16>=70,"GOOD",IF(D16>=40,"AVERAGE",IF(D16<40,"NEED IMPROVEMENT")))) -> NEED IMPROVEMENT | J16: =D16/100 -> 0.34 | K16: =IF(D16=MAX($D$5:$D$16),"TOPPER","-") -> -
A18: QUESTIONS
A19: Q1. The school pass mark is 40. In the 'Result' column, write an formula that displays "Pass" if a student's marks are 40 or above, otherwise "Fail".
A20: Q2. In the 'Grade' column, write a NESTED IF formula that assigns grades based on marks: A+ (>=90), A (>=75), B (>=60), C (>=40), F (below 40).
A21: Q3. The principal wants to award a "Merit Certificate" to students who scored between 85 and 100 (inclusive). Write an IF formula using the AND function to display "Merit" or "No Merit".
A22: Q4. Students scoring below 40 OR with a blank marks cell must appear for a re-exam. Write an IF formula using OR that displays "Re-exam" or "Cleared".
A23: Q5. Create a 4-tier performance remark using nested IF: "Excellent" (>=90), "Good" (>=70), "Average" (>=40), "Needs Improvement" (<40).
A24: Q6. Suppose a teacher accidentally divides a student's marks by zero while calculating percentage in another cell, producing a division error. Write a formula using IFERROR that displays "Check Data" instead of the error.
A25: Q7. Write an IF formula that displays "Topper" for the single highest mark in the dataset and "-" for everyone else (Hint: combine IF with MAX).

Sheet MATHS
A1: TOPIC 2: MATHEMATICAL FUNCTIONS
A3: Dataset: Quarterly Sales Report — Sunrise Retail Stores (figures in Rs.)
A4: SalesRep | B4: Region | C4: Jan Sales | D4: Feb Sales | E4: Mar Sales | F4: Emp ID | G4: Total (Q1) | H4: EVEN OR ODD | I4: SQRT | J4: 5% BONUS | K4: NORTH REGION | L4: SOUTH REGION > 45,000 | M4: AVG SALES | N4: AVG MARCH SALES | O4: ROUND | P4: ROUND UP FEB | Q4: ROUND DOWN JAN | R4: MAX | S4: MIN | T4: TOP PERFORMER
A5: Ravi Kumar | B5: North | C5: 45000 | D5: 52000 | E5: 48500 | F5: 101 | G5: =SUM(C5:E5) -> 145500 | H5: {=IF(MOD(F5:F14,2)=0,"EVEN","ODD")} -> ODD | I5: =SQRT(MAX(G5:G14)) -> 460.97722 | J5: {=POWER(G5:G14,1.05^2)} -> 492103.5 | K5: =SUMIF(B5:B14,"North",C5:C14) -> 134000 | L5: =SUMIFS(D5:D14,B5:B14,"SOUTH",C5:C14,">45000") -> 109000 | M5: =AVERAGE(C5:E5) -> 48500 | N5: =AVERAGEIF(B5:B14,"EAST",E5:E14) -> 58750 | O5: {=ROUND(G5:G14,-2)} -> 145500 | P5: {=ROUNDUP(D5:D14,-3)} -> 52000 | Q5: {=ROUNDDOWN(C5:C14,-3)} -> 45000 | R5: =MAX(G5:G14) -> 212500 | S5: =MIN(G5:G14) -> 118500 | T5: =INDEX(A5:A14,MATCH(MAX(G5:G14),G5:G14,0)) -> Farah Khan
A6: Sunita Rao | B6: South | C6: 62000 | D6: 58000 | E6: 61000 | F6: 102 | G6: =SUM(C6:E6) -> 181000 | H6: EVEN | J6: 626023.49 | M6: =AVERAGE(C6:E6) -> 60333.333 | O6: 181000 | P6: 58000 | Q6: 62000
A7: Manoj Tiwari | B7: North | C7: 38000 | D7: 41000 | E7: 39500 | F7: 103 | G7: =SUM(C7:E7) -> 118500 | H7: ODD | J7: 392441.1 | M7: =AVERAGE(C7:E7) -> 39500 | O7: 118500 | P7: 41000 | Q7: 38000
A8: Farah Khan | B8: East | C8: 71000 | D8: 68000 | E8: 73500 | F8: 104 | G8: =SUM(C8:E8) -> 212500 | H8: EVEN | J8: 747159.33 | M8: =AVERAGE(C8:E8) -> 70833.333 | O8: 212500 | P8: 68000 | Q8: 71000
A9: Deepak Joshi | B9: West | C9: 55000 | D9: 49000 | E9: 52500 | F9: 105 | G9: =SUM(C9:E9) -> 156500 | H9: ODD | J9: 533276.03 | M9: =AVERAGE(C9:E9) -> 52166.667 | O9: 156500 | P9: 49000 | Q9: 55000
A10: Kavita Menon | B10: South | C10: 48000 | D10: 51000 | E10: 47000 | F10: 106 | G10: =SUM(C10:E10) -> 146000 | H10: EVEN | J10: 493968.24 | M10: =AVERAGE(C10:E10) -> 48666.667 | O10: 146000 | P10: 51000 | Q10: 48000
A11: Suresh Pillai | B11: East | C11: 39000 | D11: 42500 | E11: 44000 | F11: 107 | G11: =SUM(C11:E11) -> 125500 | H11: ODD | J11: 418075.49 | M11: =AVERAGE(C11:E11) -> 41833.333 | O11: 125500 | P11: 43000 | Q11: 39000
A12: Neha Gupta | B12: West | C12: 66000 | D12: 64000 | E12: 69000 | F12: 108 | G12: =SUM(C12:E12) -> 199000 | H12: EVEN | J12: 695001.14 | M12: =AVERAGE(C12:E12) -> 66333.333 | O12: 199000 | P12: 64000 | Q12: 66000
A13: Arvind Nair | B13: North | C13: 51000 | D13: 53500 | E13: 50000 | F13: 109 | G13: =SUM(C13:E13) -> 154500 | H13: ODD | J13: 525767.4 | M13: =AVERAGE(C13:E13) -> 51500 | O13: 154500 | P13: 54000 | Q13: 51000
A14: Bhavna Shah | B14: South | C14: 44000 | D14: 46500 | E14: 48000 | F14: 110 | G14: =SUM(C14:E14) -> 138500 | H14: EVEN | J14: 466067.02 | M14: =AVERAGE(C14:E14) -> 46166.667 | O14: 138500 | P14: 47000 | Q14: 44000
A16: QUESTIONS
A17: Q1. calculate each sales rep's total sales for Jan+Feb+Mar.
A18: Q2. Use formula to calculate the total January sales made by reps in the 'North' region only.
A19: Q3. Use formula to calculate total February sales for reps in the 'South' region whose January sales exceeded Rs. 45,000.
A20: Q4.find the average total quarterly sales across all sales reps.
A21: Q5. find the average March sales for the 'East' region only.
A22: Q6. Use ROUND to round each rep's total sales to the nearest hundred (2 significant places from the right).
A23: Q7. Use ROUNDUP to round February sales up to the nearest thousand, and ROUNDDOWN to round January sales down to the nearest thousand.
A24: Q8. Use MAX and MIN to identify the highest and lowest total quarterly sales, and INDEX+MATCH (or a simple lookup) to name the top performer.
A25: Q9. Use MOD to check whether each Employee ID is odd or even (Hint: MOD(EmpID,2)=0 means even).
A26: Q10. The company offers a 5% year-end bonus compounded for 2 years on the total sales. Use POWER to calculate (Total*(1.05)^2), and SQRT to find the square root of the highest total sales figure.

Sheet LOGICAL QS
A1: TOPIC 3: LOGICAL FUNCTIONS (AND / OR / NOT)
A3: Dataset: Personal Loan Eligibility Screening — Trustworthy Bank Ltd.
A4: App. ID | B4: Applicant Name | C4: Age | D4: Monthly Income (Rs.) | E4: Credit Score | F4: Existing Loan (Y/N) | G4: AGE - INCOME ELIGIBILITY | H4: PRIORITY REVIEW | I4: NO EXISTING LOANS | J4: APPROVAL | K4: AGE,INCOME,CREDIT SCORE | L4: SPECIAL SENIOR SCHEME
A5: APP101 | B5: Karan Malhotra | C5: 29 | D5: 42000 | E5: 720 | F5: No | G5: =IF(AND(C5>=21,D5>=25000),"ELIGIBLE","NOT ELIGIBLE") -> ELIGIBLE | H5: =IF(OR(E5<=620,F5="YES"),"YES","NO") -> NO | I5: =IF(NOT(F5="YES"),"NO","YES") -> NO | J5: =IF(AND(C5>=21,C5<=60,OR(D5>=25000,E5>750)),"APPROVED","REJECTED") -> APPROVED | K5: =IF(AND(C5>=21,D5>=25000,E5>=650),"SATISFIED","NOTSATISFIED") -> SATISFIED | L5: =IF(AND(C5>=60,I5="NO"),"SPECIAL SENIOR SCHEME","-") -> -
A6: APP102 | B6: Sana Sheikh | C6: 34 | D6: 28000 | E6: 610 | F6: Yes | G6: =IF(AND(C6>=21,D6>=25000),"ELIGIBLE","NOT ELIGIBLE") -> ELIGIBLE | H6: =IF(OR(E6<=620,F6="YES"),"YES","NO") -> YES | I6: =IF(NOT(F6="YES"),"NO","YES") -> YES | J6: =IF(AND(C6>=21,C6<=60,OR(D6>=25000,E6>750)),"APPROVED","REJECTED") -> APPROVED | K6: =IF(AND(C6>=21,D6>=25000,E6>=650),"SATISFIED","NOTSATISFIED") -> NOTSATISFIED | L6: =IF(AND(C6>=60,I6="NO"),"SPECIAL SENIOR SCHEME","-") -> -
A7: APP103 | B7: Vikram Chawla | C7: 45 | D7: 95000 | E7: 790 | F7: No | G7: =IF(AND(C7>=21,D7>=25000),"ELIGIBLE","NOT ELIGIBLE") -> ELIGIBLE | H7: =IF(OR(E7<=620,F7="YES"),"YES","NO") -> NO | I7: =IF(NOT(F7="YES"),"NO","YES") -> NO | J7: =IF(AND(C7>=21,C7<=60,OR(D7>=25000,E7>750)),"APPROVED","REJECTED") -> APPROVED | K7: =IF(AND(C7>=21,D7>=25000,E7>=650),"SATISFIED","NOTSATISFIED") -> SATISFIED | L7: =IF(AND(C7>=60,I7="NO"),"SPECIAL SENIOR SCHEME","-") -> -
A8: APP104 | B8: Lata Desai | C8: 19 | D8: 15000 | E8: 550 | F8: No | G8: =IF(AND(C8>=21,D8>=25000),"ELIGIBLE","NOT ELIGIBLE") -> NOT ELIGIBLE | H8: =IF(OR(E8<=620,F8="YES"),"YES","NO") -> YES | I8: =IF(NOT(F8="YES"),"NO","YES") -> NO | J8: =IF(AND(C8>=21,C8<=60,OR(D8>=25000,E8>750)),"APPROVED","REJECTED") -> REJECTED | K8: =IF(AND(C8>=21,D8>=25000,E8>=650),"SATISFIED","NOTSATISFIED") -> NOTSATISFIED | L8: =IF(AND(C8>=60,I8="NO"),"SPECIAL SENIOR SCHEME","-") -> -
A9: APP105 | B9: Imran Ali | C9: 52 | D9: 60000 | E9: 640 | F9: Yes | G9: =IF(AND(C9>=21,D9>=25000),"ELIGIBLE","NOT ELIGIBLE") -> ELIGIBLE | H9: =IF(OR(E9<=620,F9="YES"),"YES","NO") -> YES | I9: =IF(NOT(F9="YES"),"NO","YES") -> YES | J9: =IF(AND(C9>=21,C9<=60,OR(D9>=25000,E9>750)),"APPROVED","REJECTED") -> APPROVED | K9: =IF(AND(C9>=21,D9>=25000,E9>=650),"SATISFIED","NOTSATISFIED") -> NOTSATISFIED | L9: =IF(AND(C9>=60,I9="NO"),"SPECIAL SENIOR SCHEME","-") -> -
A10: APP106 | B10: Ritu Bhatia | C10: 26 | D10: 31000 | E10: 705 | F10: No | G10: =IF(AND(C10>=21,D10>=25000),"ELIGIBLE","NOT ELIGIBLE") -> ELIGIBLE | H10: =IF(OR(E10<=620,F10="YES"),"YES","NO") -> NO | I10: =IF(NOT(F10="YES"),"NO","YES") -> NO | J10: =IF(AND(C10>=21,C10<=60,OR(D10>=25000,E10>750)),"APPROVED","REJECTED") -> APPROVED | K10: =IF(AND(C10>=21,D10>=25000,E10>=650),"SATISFIED","NOTSATISFIED") -> SATISFIED | L10: =IF(AND(C10>=60,I10="NO"),"SPECIAL SENIOR SCHEME","-") -> -
A11: APP107 | B11: Sameer Joshi | C11: 63 | D11: 48000 | E11: 680 | F11: No | G11: =IF(AND(C11>=21,D11>=25000),"ELIGIBLE","NOT ELIGIBLE") -> ELIGIBLE | H11: =IF(OR(E11<=620,F11="YES"),"YES","NO") -> NO | I11: =IF(NOT(F11="YES"),"NO","YES") -> NO | J11: =IF(AND(C11>=21,C11<=60,OR(D11>=25000,E11>750)),"APPROVED","REJECTED") -> REJECTED | K11: =IF(AND(C11>=21,D11>=25000,E11>=650),"SATISFIED","NOTSATISFIED") -> SATISFIED | L11: =IF(AND(C11>=60,I11="NO"),"SPECIAL SENIOR SCHEME","-") -> SPECIAL SENIOR SCHEME
A12: APP108 | B12: Anjali Kulkarni | C12: 38 | D12: 27000 | E12: 760 | F12: Yes | G12: =IF(AND(C12>=21,D12>=25000),"ELIGIBLE","NOT ELIGIBLE") -> ELIGIBLE | H12: =IF(OR(E12<=620,F12="YES"),"YES","NO") -> YES | I12: =IF(NOT(F12="YES"),"NO","YES") -> YES | J12: =IF(AND(C12>=21,C12<=60,OR(D12>=25000,E12>750)),"APPROVED","REJECTED") -> APPROVED | K12: =IF(AND(C12>=21,D12>=25000,E12>=650),"SATISFIED","NOTSATISFIED") -> SATISFIED | L12: =IF(AND(C12>=60,I12="NO"),"SPECIAL SENIOR SCHEME","-") -> -
A13: APP109 | B13: Tarun Reddy | C13: 24 | D13: 22000 | E13: 590 | F13: No | G13: =IF(AND(C13>=21,D13>=25000),"ELIGIBLE","NOT ELIGIBLE") -> NOT ELIGIBLE | H13: =IF(OR(E13<=620,F13="YES"),"YES","NO") -> YES | I13: =IF(NOT(F13="YES"),"NO","YES") -> NO | J13: =IF(AND(C13>=21,C13<=60,OR(D13>=25000,E13>750)),"APPROVED","REJECTED") -> REJECTED | K13: =IF(AND(C13>=21,D13>=25000,E13>=650),"SATISFIED","NOTSATISFIED") -> NOTSATISFIED | L13: =IF(AND(C13>=60,I13="NO"),"SPECIAL SENIOR SCHEME","-") -> -
A14: APP110 | B14: Pooja Agarwal | C14: 41 | D14: 110000 | E14: 800 | F14: No | G14: =IF(AND(C14>=21,D14>=25000),"ELIGIBLE","NOT ELIGIBLE") -> ELIGIBLE | H14: =IF(OR(E14<=620,F14="YES"),"YES","NO") -> NO | I14: =IF(NOT(F14="YES"),"NO","YES") -> NO | J14: =IF(AND(C14>=21,C14<=60,OR(D14>=25000,E14>750)),"APPROVED","REJECTED") -> APPROVED | K14: =IF(AND(C14>=21,D14>=25000,E14>=650),"SATISFIED","NOTSATISFIED") -> SATISFIED | L14: =IF(AND(C14>=60,I14="NO"),"SPECIAL SENIOR SCHEME","-") -> -
A16: QUESTIONS
A17: Q1. Bank policy: an applicant is 'Age-Income Eligible' only if Age is 21 or above AND Monthly Income is Rs. 25,000 or above. Write a formula using AND to return TRUE/FALSE.
A18: Q2. Applicants need a 'Priority Review' if their Credit Score is below 620 OR they already have an existing loan. Write a formula using OR.
A19: Q3. Write a formula using NOT to flag applicants who do NOT have an existing loan (result should be TRUE for 'No').
A20: Q4. Combine IF, AND and OR: an applicant is 'Approved' if (Age is between 21 and 60 inclusive) AND (Income >= 25000 OR Credit Score > 750); otherwise 'Rejected'.
A21: Q5. Write a formula using AND with three conditions to check if an applicant simultaneously has Age>=21, Income>=25000, and Credit Score>=650.
A22: Q6. Senior citizens (Age > 60) with no existing loan get a 'Special Senior Scheme' offer. Write a nested formula using IF and AND to display this remark.

Sheet FIND AND SEARCH QS
A1: TOPIC 7: FIND & SEARCH FUNCTIONS
A3: Dataset: Employee Contact Directory — Skyline Corp HR Department
A4: Employee Name | B4: Email Address | C4: Full Address | D4: Username (Q2) | E4: Domain (Q4) | F4: City (Q6) | G4: @ | H4: GMAIL
A5: Nikhil Rane | B5: nikhil.rane@gmail.com | C5: 204, MG Road, Pune, 411001 | D5: nikhil.rane | E5: =RIGHT(B5,LEN(B5)-FIND("@",B5)) -> gmail.com | F5: PUNE | G5: {=FIND("@",B5:B10)} -> 12 | H5: =IF(ISNUMBER(SEARCH("gmail",B5)),"YES","NO") -> YES | I5: =LEFT(C5,FIND(",",C5)-1) -> 204
A6: Sarah MATHEW | B6: sarah.mathew@OUTLOOK.com | C6: 12, Park Street, Kolkata, 700016 | D6: sarah.mathew | E6: =RIGHT(B6,LEN(B6)-FIND("@",B6)) -> OUTLOOK.com | F6: . | G6: 13 | H6: =IF(ISNUMBER(SEARCH("gmail",B6)),"YES","NO") -> NO | I6: =LEFT(C6,FIND(",",C6)-1) -> 12
A7: Farhan Sheikh | B7: farhan.s@yahoo.co.in | C7: 45, Anna Salai, Chennai, 600002 | D7: farhan.s | E7: =RIGHT(B7,LEN(B7)-FIND("@",B7)) -> yahoo.co.in | F7: CHENNAI | G7: 9 | H7: =IF(ISNUMBER(SEARCH("gmail",B7)),"YES","NO") -> NO | I7: =LEFT(C7,FIND(",",C7)-1) -> 45
A8: Divya Krishnan | B8: divya.k@gmail.com | C8: 7, Residency Road, Bengaluru, 560025 | D8: divya.k | E8: =RIGHT(B8,LEN(B8)-FIND("@",B8)) -> gmail.com | F8: BENGALURU | G8: 8 | H8: =IF(ISNUMBER(SEARCH("gmail",B8)),"YES","NO") -> YES | I8: =LEFT(C8,FIND(",",C8)-1) -> 7
A9: Om Prakash | B9: om.prakash@COMPANYMAIL.com | C9: 19, Civil Lines, Nagpur, 440001 | D9: om.prakash | E9: =RIGHT(B9,LEN(B9)-FIND("@",B9)) -> COMPANYMAIL.com | F9: NAGPUR | G9: 11 | H9: =IF(ISNUMBER(SEARCH("gmail",B9)),"YES","NO") -> NO | I9: =LEFT(C9,FIND(",",C9)-1) -> 19
A10: Leena D'Souza | B10: leena.ds@gmail.com | C10: 88, Linking Road, Mumbai, 400050 | D10: leena.ds | E10: =RIGHT(B10,LEN(B10)-FIND("@",B10)) -> gmail.com | F10: MUMBAI | G10: 9 | H10: =IF(ISNUMBER(SEARCH("gmail",B10)),"YES","NO") -> YES | I10: =LEFT(C10,FIND(",",C10)-1) -> 88
A12: QUESTIONS
A13: Q1. Use FIND to return the position (character number) of the '@' symbol within each Email Address.
A14: Q2. Use MID together with FIND to extract the 'Username' portion of the email (the text before '@').
A15: Q3. One employee's email contains 'OUTLOOK' in uppercase. Use SEARCH (which is case-insensitive) to check if the text 'gmail' appears anywhere in each email — compare this to using FIND for the same check on 'GMAIL' and explain the difference in results.
A16: Q4. Use RIGHT combined with LEN and FIND to extract the 'Domain' portion of the email (the text after '@').
A17: Q5. In the 'Full Address' column, use FIND to locate the position of the first comma, then use LEFT to extract the house/street portion before it.
A18: Q6. Use FIND (with nested FIND/SUBSTITUTE as needed) to extract the 'City' name, which appears between the 2nd and 3rd commas in the Full Address.

Sheet DATE&TIME
A1: TOPIC 9: DATE & TIME FUNCTIONS
A3: Dataset A: Employee Attendance Log — 18 Aug 2026
A4: Employee | B4: Date of Joining | C4: Check-In | D4: Check-Out | E4: Hours Worked (Q9) | F4: Tenure in Days (Q1) | G4: Day of Week (Q6) | H4: DATE DIFF
A5: Rahul Batra | B5: 43536 | C5: 0.38541667 | D5: 0.75347222 | E5: =D5-C5 -> 0.36805556 | F5: =TODAY()-B5 -> 2776 | G5: =TEXT(B5,"DDDD") -> Tuesday
A6: Simran Kaur | B6: 44378 | C6: 0.40277778 | D6: 0.74305556 | E6: =D6-C6 -> 0.34027778 | F6: =TODAY()-B6 -> 1934 | G6: =TEXT(B6,"DDDD") -> Thursday
A7: Devendra Rao | B7: 43062 | C7: 0.37847222 | D7: 0.79166667 | E7: =D7-C7 -> 0.41319444 | F7: =TODAY()-B7 -> 3250 | G7: =TEXT(B7,"DDDD") -> Thursday
A8: Ayesha Siddiqui | B8: 44935 | C8: 0.41666667 | D8: 0.77083333 | E8: =D8-C8 -> 0.35416667 | F8: =TODAY()-B8 -> 1377 | G8: =TEXT(B8,"DDDD") -> Monday
A9: Manish Pillai | B9: 43969 | C9: 0.39236111 | D9: 0.75694444 | E9: =D9-C9 -> 0.36458333 | F9: =TODAY()-B9 -> 2343 | G9: =TEXT(B9,"DDDD") -> Monday
A12: Dataset B: Project Timeline — Website Revamp Project
A13: Task | B13: Start Date | C13: End Date | D13: Working Days (Q3) | E13: 10-Workday Deadline (Q4) | F13: Probation/Review +3mo (Q7) | G13: Month-End (Q8) | H13: YEAR | I13: MONTH | J13: DAY
A14: Requirement Gathering | B14: 46266 | C14: 46275 | D14: =NETWORKDAYS(B14,C14) -> 8 | E14: =WORKDAY(B14,10) -> 46280 | F14: =EDATE(B14,3) -> 46357 | G14: =EOMONTH(B14,0) -> 46295 | H14: =YEAR(B14) -> 2026 | I14: =MONTH(B14) -> 9 | J14: =DAY(B14) -> 1
A15: UI/UX Design | B15: 46276 | C15: 46290 | D15: =NETWORKDAYS(B15,C15) -> 11 | E15: =WORKDAY(B15,10) -> 46290 | F15: =EDATE(B15,3) -> 46367 | G15: =EOMONTH(B15,0) -> 46295 | H15: =YEAR(B15) -> 2026 | I15: =MONTH(B15) -> 9 | J15: =DAY(B15) -> 11
A16: Development | B16: 46291 | C16: 46315 | D16: =NETWORKDAYS(B16,C16) -> 17 | E16: =WORKDAY(B16,10) -> 46304 | F16: =EDATE(B16,3) -> 46382 | G16: =EOMONTH(B16,0) -> 46295 | H16: =YEAR(B16) -> 2026 | I16: =MONTH(B16) -> 9 | J16: =DAY(B16) -> 26
A17: Testing | B17: 46316 | C17: 46326 | D17: =NETWORKDAYS(B17,C17) -> 8 | E17: =WORKDAY(B17,10) -> 46330 | F17: =EDATE(B17,3) -> 46408 | G17: =EOMONTH(B17,0) -> 46326 | H17: =YEAR(B17) -> 2026 | I17: =MONTH(B17) -> 10 | J17: =DAY(B17) -> 21
A20: QUESTIONS
A21: Q1. Using Dataset A, calculate each employee's 'Tenure in Days' as TODAY() minus their Date of Joining.
A22: Q2. Extend Q1: use DATEDIF to express each employee's tenure in complete YEARS and MONTHS (e.g., '7 years 5 months').
A23: Q3. Using Dataset B, use NETWORKDAYS to calculate the number of working days (excluding weekends) between each task's Start Date and End Date.
A24: Q4. Using Dataset B, use WORKDAY to calculate the deadline date that falls exactly 10 working days after each task's Start Date.
A25: Q5. Use YEAR, MONTH, and DAY to extract each of these components separately from the 'Start Date' column in Dataset B.
A26: Q6. Use WEEKDAY (or TEXT with a date format) to determine the day of the week (e.g., Monday, Tuesday) for each employee's Date of Joining in Dataset A.
A27: Q7. New employees must complete a 3-month probation. Use EDATE to calculate the 'Probation Review Date' as 3 months after each task's Start Date in Dataset B.
A28: Q8. Use EOMONTH to find the last date of the month in which each task in Dataset B starts.
A29: Q9. Using Dataset A, calculate 'Hours Worked' as Check-Out time minus Check-In time, formatted to show hours and minutes.

Sheet REF..
A1: TOPIC 8: REFERENCE FUNCTIONS (INDEX / MATCH / OFFSET / INDIRECT / ROW / COLUMN)
A3: Dataset: 6-Month Sales Matrix — Product vs Month (Units Sold), Table starts at A5
A4: Product | B4: Jan | C4: Feb | D4: Mar | E4: Apr | F4: May | G4: Jun
A5: Widget A | B5: 120 | C5: 135 | D5: 128 | E5: 140 | F5: 150 | G5: 145 | H5: =INDEX(B5:G9,3,4) -> 220 | I5: =MAX(G5:G9) -> 225
A6: Widget B | B6: 95 | C6: 102 | D6: 110 | E6: 98 | F6: 115 | G6: 120 | H6: =MATCH("Apr",B4:G4,0) -> 4
A7: Widget C | B7: 200 | C7: 210 | D7: 195 | E7: 220 | F7: 230 | G7: 225 | H7: =INDEX(B5:G9,2,5) -> 115
A8: Widget D | B8: 60 | C8: 58 | D8: 65 | E8: 70 | F8: 68 | G8: 75 | H8: =OFFSET(B5,2,3) -> 220
A9: Widget E | B9: 150 | C9: 148 | D9: 160 | E9: 155 | F9: 165 | G9: 170 | H9: {=INDIRECT(A1&B1)} -> #REF!
A11: QUESTIONS
H12: =ROW()-ROW($A$5)+1 -> 8
A13: Q2. Use MATCH to find which column number 'Apr' occupies within the header row.
A14: Q3. Combine INDEX and MATCH to look up the sales of 'Widget B' in 'May' without hardcoding row or column numbers.
A15: Q4. Starting from the 'Widget A / Jan' cell as the reference point, use OFFSET to retrieve the value that is 2 rows down and 3 columns right of it. Which product/month does this correspond to?
A16: Q5. Use INDIRECT to build a cell reference dynamically from text, e.g. combine a row number and column letter typed in separate cells to fetch a value from the table.
A17: Q6. Use ROW() and COLUMN() to auto-generate a serial number list (1, 2, 3...) next to the Product column without typing the numbers manually.
A18: Q7. Use INDEX + MATCH (for the row) with the MAX function to find the product name with the highest sales in 'Jun', and use ADDRESS to return that cell's address.

Sheet LOOKUP QS
A1: TOPIC 4: LOOKUP FUNCTIONS (VLOOKUP / HLOOKUP / INDEX-MATCH)
A3: Dataset A: Product Master — Zenith Electronics Store
A4: ProductID | B4: Product Name | C4: Category | D4: Unit Price (Rs.)
A5: P001 | B5: LED Bulb 9W | C5: Lighting | D5: 120
A6: P002 | B6: Ceiling Fan | C6: Appliances | D6: 1850
A7: P003 | B7: USB Cable | C7: Accessories | D7: 199
A8: P004 | B8: Bluetooth Speaker | C8: Electronics | D8: 1499
A9: P005 | B9: Wall Clock | C9: Home Decor | D9: 350
A10: P006 | B10: Extension Board | C10: Accessories | D10: 450
A11: P007 | B11: Table Lamp | C11: Lighting | D11: 699
A12: P008 | B12: Mixer Grinder | C12: Appliances | D12: 2999
A15: Dataset B: Order Details (Order Day — 14 Aug 2026)
A16: OrderID | B16: ProductID | C16: Quantity | D16: Product Name (Q1) | E16: Unit Price (Q2) | F16: Total Amount (Q3)
A17: ORD-501 | B17: P003 | C17: 5 | D17: =VLOOKUP(B5,A5:A12,2,FALSE) -> #N/A
A18: ORD-502 | B18: P002 | C18: 2
A19: ORD-503 | B19: P006 | C19: 8
A20: ORD-504 | B20: P008 | C20: 1
A21: ORD-505 | B21: P001 | C21: 12
A22: ORD-506 | B22: P004 | C22: 3
A25: Dataset C: Quantity-based Discount Slabs (for approximate-match VLOOKUP)
A26: Min Qty | B26: Discount %
A27: 0 | B27: 0%
A28: 5 | B28: 5%
A29: 10 | B29: 10%
A30: 20 | B30: 15%
A33: Dataset D: Two-way Matrix — Region-wise Monthly Revenue (Rs. '000)
A34: Region | B34: Jan | C34: Feb | D34: Mar | E34: Apr
A35: North | B35: 320 | C35: 340 | D35: 310 | E35: 360
A36: South | B36: 410 | C36: 400 | D36: 430 | E36: 420
A37: East | B37: 280 | C37: 300 | D37: 295 | E37: 310
A38: West | B38: 350 | C38: 365 | D38: 355 | E38: 370
A41: QUESTIONS
A42: Q1. In Dataset B, use VLOOKUP to fetch the 'Product Name' for each OrderID by looking up ProductID in Dataset A.
A43: Q2. Use VLOOKUP to fetch the 'Unit Price' for each order, then calculate 'Total Amount' as Unit Price x Quantity.
A44: Q3. Rewrite Question 1 using INDEX + MATCH instead of VLOOKUP, and confirm you get the same product names.
A45: Q4. Use VLOOKUP with an APPROXIMATE match (TRUE / 1) on Dataset C to find the discount % applicable to an order with Quantity=8 and Quantity=15.
A46: Q5. Using Dataset D, write an HLOOKUP formula to find North region's revenue for 'Mar'.
A47: Q6. Using Dataset D, write an INDEX + MATCH + MATCH (two-way lookup) formula to find the revenue for Region='East' and Month='Feb' without hardcoding row/column numbers.
A48: Q7. A customer asks: 'What product costs exactly Rs. 1499?' Write a formula (INDEX+MATCH or VLOOKUP with a helper) to return the Product Name for a given Unit Price.

Sheet RANK QS
A1: TOPIC 5: RANK FUNCTION
A3: Dataset: District Athletics Meet — 100m Sprint & Overall Points
